<mujoco model="xarm7_body">
  <body name="xarm7_body">
    <body name="link_base" pos="0 0 0" childclass="xarm7">
      <inertial pos="-0.021131 -0.0016302 0.056488" quat="0.696843 0.20176 0.10388 0.677479" mass="9.6955" diaginertia="0.03766 0.031057 0.025836"/>
      <geom material="white" mesh="link_base"/>
      <body name="link1" pos="0 0 0.267" quat="0.70711 0 0 0.70711">
        <inertial pos="5.81615e-05 -0.0453627 0.0781599" quat="0.883405 0.467289 4.67642e-05 7.42927e-05" mass="3.813" diaginertia="0.0123725 0.00686035 0.00884269"/>
        <joint name="joint1" axis="0 0 1"/>
        <geom material="white" mesh="link1"/>
        <site name="force_sensor" pos="-9e-05 -0.02 0.07816"/>
        <body name="link2" pos="0 -0.11 0.092" quat="0.70711 0 0 0.70711">
          <inertial pos="1.02647e-05 0.0916639 -5.49827e-05" quat="0.500012 -0.499995 -0.499994 0.500002" mass="4.26626" diaginertia="0.0223777 0.00445769 0.0201591"/>
          <joint name="joint2" axis="0 0 1"/>
          <geom material="white" mesh="link2"/>
          <body name="link3" pos="0 -0.0825 0" quat="0.70711 0 0 0.70711">
            <inertial pos="-3.69773e-05 0.0109005 0.02599" quat="0.50003 0.499975 -0.499964 -0.500031" mass="3.4462" diaginertia="0.00749484 0.00629947 0.00358298"/>
            <joint name="joint3" axis="0 0 1"/>
            <geom material="white" mesh="link3"/>
            <body name="link4" pos="0 0.0825 0.0" quat="0.70711 0 0 0.70711">
              <inertial pos="-1.2795e-05 0.0577991 -0.0468973" quat="0.500016 0.499995 -0.499997 -0.500011" mass="1.97616" diaginertia="0.0059885 0.00341876 0.0058087"/>
              <joint name="joint4" axis="0 0 1"/>
              <geom material="white" mesh="link4"/>
              <body name="link5" pos="0 -0.0825 0.0" quat="0.70711 0 0 0.70711">
                <inertial pos="1.63521e-05 0.031042 -0.0203656" quat="0.499989 0.500001 -0.499994 -0.500017" mass="1.4" diaginertia="0.00260037 0.00194641 0.00243634"/>
                <joint name="joint5" axis="0 0 1"/>
                <geom material="white" mesh="link5"/>
                <body name="link6" pos="0 0.071 0.0" quat="0.70711 0 0 0.70711">
                  <inertial pos="3.17377e-06 -0.00753547 0.0486608" quat="0.500004 0.500005 -0.499992 -0.499999" mass="1.09834" diaginertia="0.00105083 0.000848253 0.000736388"/>
                  <joint name="joint6" axis="0 0 1"/>
                  <geom material="white" mesh="link6"/>
                  <body name="link7" pos="0 -0.071 0.0" quat="0.70711 0 0 0.70711">
                    <inertial pos="1.18028e-05 -0.00882174 0.08393" quat="0.582838 -0.3972 -0.397203 0.582855" mass="0.489949" diaginertia="0.000545804 0.00063588 0.000433156"/>
                    <joint name="joint7" axis="0 0 1"/>
                    <geom material="white" mesh="link7"/>
                    <body name="end_tool" pos="0.0 0.0555 0.0879">
                      <inertial pos="-0.004367 -0.018967 0.053471" quat="0.498683 -0.501312 0.499118 0.500881" mass="0.691368" diaginertia="0.00019308 0.000296209 0.000155315"/>
                      <geom material="gray" mesh="end_tool"/>
                      <body name="base_link" pos="-0.03346 0.0 0.07">
                        <inertial pos="0.000753446 -0.000454315 0.0556814" quat="0.500192 0.499664 0.499703 0.500441"
                        mass="0.54156" diaginertia="0.000471093 0.000332307 0.000254799"/>
                      <geom mesh="base_link"/>
                      <body name="left_outer_knuckle" pos="0 0.035 0.059098">
                        <inertial pos="0 0.021559 0.015181" quat="0.47789 0.87842 0 0" mass="0.033618"
                          diaginertia="1.9111e-05 1.79089e-05 1.90167e-06"/>
                        <joint name="left_driver_joint" axis="1 0 0" class="driver"/>
                        <geom material="black" mesh="left_outer_knuckle"/>
                      </body>
                      <body name="left_inner_knuckle" pos="0 0.02 0.074098">
                        <inertial pos="1.86601e-06 0.0220468 0.0261335" quat="0.664139 -0.242732 0.242713 0.664146"
                          mass="0.0230126" diaginertia="8.34216e-06 6.0949e-06 2.75601e-06"/>
                        <joint name="left_inner_knuckle_joint" axis="1 0 0" class="spring_link"/>
                        <geom material="black" mesh="left_inner_knuckle"/>
                        <body name="left_finger" pos="0 0.035465 0.042039">
                          <inertial pos="0 -0.016413 0.029258" quat="0.697634 0.115353 -0.115353 0.697634"
                                    mass="0.048304" diaginertia="1.88037e-05 1.7493e-05 3.56792e-06"/>
                          <joint name="left_finger_joint" axis="-1 0 0" class="follower"/>
                          <geom material="black" mesh="left_finger" contype="0" conaffinity="0" pos="0 0.015 -0.015"/>
                          <body pos="0.0 -0.006 0.0275" euler="0.05 0 0">
                            <geom type="box" pos="0.0 0.0 0.009" size="0.014 0.005 0.009" friction="0.7"
                                  solimp="0.95 0.99 0.001" solref="0.004 1" priority="1" condim="3" group="3"
                                  rgba="0.55 0.55 0.55 1"/>
                            <geom type="box" pos="0.0 0.0 -0.009" size="0.014 0.005 0.009" friction="0.6"
                                  solimp="0.95 0.99 0.001" solref="0.004 1" priority="1" condim="3" group="3"
                                  rgba="0.45 0.45 0.45 1"/>
                          </body>
                        </body>
                      </body>
                      <body name="right_outer_knuckle" pos="0 -0.035 0.059098">
                        <inertial pos="0 -0.021559 0.015181" quat="0.87842 0.47789 0 0" mass="0.033618"
                          diaginertia="1.9111e-05 1.79089e-05 1.90167e-06"/>
                        <joint name="right_driver_joint" axis="-1 0 0" class="driver"/>
                        <geom material="black" mesh="right_outer_knuckle"/>
                      </body>
                      <body name="right_inner_knuckle" pos="0 -0.02 0.074098">
                        <inertial pos="1.866e-06 -0.022047 0.026133" quat="0.66415 0.242702 -0.242721 0.664144"
                          mass="0.023013" diaginertia="8.34209e-06 6.0949e-06 2.75601e-06"/>
                        <joint name="right_inner_knuckle_joint" axis="-1 0 0" class="spring_link"/>
                        <geom material="black" mesh="right_inner_knuckle"/>
                        <body name="right_finger" pos="0 -0.035465 0.042039">
                          <inertial pos="0 0.016413 0.029258" quat="0.697634 -0.115356 0.115356 0.697634"
                            mass="0.048304" diaginertia="1.88038e-05 1.7493e-05 3.56779e-06"/>
                          <joint name="right_finger_joint" axis="1 0 0" class="follower"/>
                          <geom material="black" mesh="right_finger" contype="0" conaffinity="0" pos="0 -0.015 -0.015"/>
                          <body pos="0.0 0.006 0.0275" euler="-0.05 0 0">
                            <geom type="box" pos="0.0 0.0 0.009" size="0.014 0.005 0.009" friction="0.7"
                                  solimp="0.95 0.99 0.001" solref="0.004 1" priority="1" condim="3" group="3"
                                  rgba="0.55 0.55 0.55 1"/>
                            <geom type="box" pos="0.0 0.0 -0.009" size="0.014 0.005 0.009" friction="0.6"
                                  solimp="0.95 0.99 0.001" solref="0.004 1" priority="1" condim="3" group="3"
                                  rgba="0.45 0.45 0.45 1"/>
                          </body>
                        </body>
                      </body>
                      <site name="link_tcp" pos="0 0 .172"/>
                    </body>
                    <!-- hand camera -->
                    <body name="hand_camera_link">
                      <geom material="gray" mesh="d435_with_cam_stand_visual" contype="0" conaffinity="0"/>
                      <geom material="gray" mesh="d435_with_cam_stand_collision" group="3"/>
                      <camera name="hand" fovy="62" pos="0.06746 0.0 0.0237" euler="0.0 3.1415 1.5708"/>
                    </body>
                  </body>
                </body>
              </body>
            </body>
          </body>
        </body>
      </body>
    </body>
  </body>
</mujoco>
