<mujoco model="ur5e_leap_scene_legacy">
  <include file="../leap_rh_mjx.xml"/>

  <visual>
    <global azimuth="120" elevation="-20"/>
  </visual>

  <default>
    <position kp="200" inheritrange="1"/>
  </default>

  <worldbody>
    <geom name="floor" pos="0 0 -0.5" size="0 0 0.01" type="plane" contype="0" conaffinity="0"/>

    <body name="ur5e_base" pos="0 0 0" quat="1 0 0 0">
      <geom type="box" size="0.02 0.02 0.02" mass="0.1" contype="0" conaffinity="0" group="2"/>
      <body name="ur5e_shoulder" pos="0 0 0.1625">
        <joint name="ur5e_j1" type="hinge" axis="0 0 1" limited="true" range="-6.283 6.283"/>
        <geom type="box" size="0.015 0.015 0.015" mass="0.1" contype="0" conaffinity="0" group="2"/>
        <body name="ur5e_upperarm" pos="0 0 0">
          <joint name="ur5e_j2" type="hinge" axis="0 1 0" limited="true" range="-6.283 6.283"/>
          <geom type="box" size="0.015 0.015 0.015" mass="0.1" contype="0" conaffinity="0" group="2"/>
          <body name="ur5e_forearm" pos="-0.425 0 0">
            <joint name="ur5e_j3" type="hinge" axis="0 1 0" limited="true" range="-6.283 6.283"/>
            <geom type="box" size="0.015 0.015 0.015" mass="0.1" contype="0" conaffinity="0" group="2"/>
            <body name="ur5e_wrist1" pos="-0.3922 0 0">
              <joint name="ur5e_j4" type="hinge" axis="0 1 0" limited="true" range="-6.283 6.283"/>
              <geom type="box" size="0.012 0.012 0.012" mass="0.08" contype="0" conaffinity="0" group="2"/>
              <body name="ur5e_wrist2" pos="0 0 0.1333">
                <joint name="ur5e_j5" type="hinge" axis="0 0 1" limited="true" range="-6.283 6.283"/>
                <geom type="box" size="0.01 0.01 0.01" mass="0.06" contype="0" conaffinity="0" group="2"/>
                <body name="ur5e_flange" pos="0 0 0.1993">
                  <joint name="ur5e_j6" type="hinge" axis="0 1 0" limited="true" range="-6.283 6.283"/>
                  <geom type="box" size="0.008 0.008 0.008" mass="0.05" contype="0" conaffinity="0" group="2"/>
                  <site name="ur5e_tool0" pos="0 0 0" group="4"/>
                </body>
              </body>
            </body>
          </body>
        </body>
      </body>
    </body>
  </worldbody>

  <equality>
    <weld body1="ur5e_flange" body2="leap_mount" solref="0.02 1" solimp="0.9 0.95 0.001"/>
  </equality>

  <actuator>
    <position name="ur5e_j1_act" joint="ur5e_j1"/>
    <position name="ur5e_j2_act" joint="ur5e_j2"/>
    <position name="ur5e_j3_act" joint="ur5e_j3"/>
    <position name="ur5e_j4_act" joint="ur5e_j4"/>
    <position name="ur5e_j5_act" joint="ur5e_j5"/>
    <position name="ur5e_j6_act" joint="ur5e_j6"/>
  </actuator>
</mujoco>


