<mujoco model="leap_rh_direct">
  <compiler angle="radian" autolimits="true" meshdir=""/>

  <option timestep="0.01" integrator="Euler" iterations="5" ls_iterations="8">
    <flag eulerdamp="disable"/>
  </option>

  <custom>
    <numeric data="30" name="max_contact_points"/>
    <numeric data="12" name="max_geom_pairs"/>
  </custom>

  <asset>
    <material name="leap_black" rgba="0.2 0.2 0.2 1"/>
    <material name="leap_gray" rgba="0.5 0.5 0.5 1"/>
    <mesh name="leap_mount" file="../../../../../mujoco_playground/_src/manipulation/my_leap_hand/xmls/meshes/leap_mount.obj"/>

    <mesh name="palm" file="../../../../../mujoco_menagerie/leap_hand/assets/palm_right.obj"/>
    <mesh name="base" file="../../../../../mujoco_menagerie/leap_hand/assets/base.obj"/>
    <mesh name="proximal" file="../../../../../mujoco_menagerie/leap_hand/assets/proximal.obj"/>
    <mesh name="medial" file="../../../../../mujoco_menagerie/leap_hand/assets/medial.obj"/>
    <mesh name="distal" file="../../../../../mujoco_menagerie/leap_hand/assets/distal.obj"/>
    <mesh name="tip" file="../../../../../mujoco_menagerie/leap_hand/assets/tip.obj"/>
    <mesh name="thumb_base" file="../../../../../mujoco_menagerie/leap_hand/assets/thumb_base.obj"/>
    <mesh name="thumb_proximal" file="../../../../../mujoco_menagerie/leap_hand/assets/thumb_proximal.obj"/>
    <mesh name="thumb_distal" file="../../../../../mujoco_menagerie/leap_hand/assets/thumb_distal.obj"/>
    <mesh name="thumb_tip" file="../../../../../mujoco_menagerie/leap_hand/assets/thumb_tip.obj"/>
  </asset>

  <default>
    <default class="leap_rh">
      <geom group="3" friction="0.2" solref="0.02 1.5" solimp="0.9 0.99 0.001"/>
      <default class="leap_visual">
        <geom group="2" type="mesh" contype="0" conaffinity="0" density="0" material="leap_black"/>
      </default>
      <default class="tip">
        <geom size="0.01 0.012 0.016" pos="-0.0012969 -0.0335524 0.0145207" quat="0.703552 0.709596 -0.0292107 -0.0252203" type="box" friction="0.7 0.05 0.0002" rgba=".5 .5 .5 .3"/>
      </default>
      <default class="thumb_tip">
        <geom size="0.01 0.012 0.016" pos="-0.00127744 -0.0455619 -0.0144774" quat="0.708101 0.705072 -0.0294902 -0.024426" type="box" friction="0.7 0.05 0.0002" rgba=".5 .5 .5 .3"/>
      </default>

      <position kp="3.0" inheritrange="1"/>
      <joint axis="0 0 -1" damping="0.2" armature="0.00149376" actuatorfrcrange="-0.2196 0.2196" frictionloss="0.02"/>

      <default class="mcp">
        <joint range="-0.314 2.23"/>
      </default>
      <default class="rot">
        <joint range="-1.047 1.047"/>
      </default>
      <default class="pip">
        <joint range="-0.506 1.885"/>
      </default>
      <default class="dip">
        <joint range="-0.366 2.042"/>
      </default>
      <default class="thumb_cmc">
        <joint range="-0.349 2.094"/>
      </default>
      <default class="thumb_axl">
        <joint range="-0.349 2.094"/>
      </default>
      <default class="thumb_mcp">
        <joint range="-0.47 2.443"/>
      </default>
      <default class="thumb_ipl">
        <joint range="-1.34 1.88"/>
      </default>

    </default>
  </default>

  <contact>
    <exclude body1="palm" body2="if_bs"/>
    <exclude body1="palm" body2="mf_bs"/>
    <exclude body1="palm" body2="rf_bs"/>
    <exclude body1="palm" body2="th_mp"/>

    <exclude body1="palm" body2="if_px"/>
    <exclude body1="palm" body2="mf_px"/>
    <exclude body1="palm" body2="rf_px"/>
    <exclude body1="palm" body2="th_bs"/>

    <exclude body1="palm" body2="if_md"/>
    <exclude body1="palm" body2="mf_md"/>
    <exclude body1="palm" body2="rf_md"/>
    <exclude body1="palm" body2="th_px"/>

    <exclude body1="leap_mount" body2="if_bs"/>
    <exclude body1="leap_mount" body2="mf_bs"/>
    <exclude body1="leap_mount" body2="rf_bs"/>
    <exclude body1="leap_mount" body2="th_mp"/>

    <exclude body1="leap_mount" body2="if_px"/>
    <exclude body1="leap_mount" body2="mf_px"/>
    <exclude body1="leap_mount" body2="rf_px"/>
    <exclude body1="leap_mount" body2="th_bs"/>

    <exclude body1="leap_mount" body2="if_md"/>
    <exclude body1="leap_mount" body2="mf_md"/>
    <exclude body1="leap_mount" body2="rf_md"/>
    <exclude body1="leap_mount" body2="th_px"/>

    <exclude body1="if_bs" body2="mf_bs"/>
    <exclude body1="if_bs" body2="rf_bs"/>
    <exclude body1="mf_bs" body2="rf_bs"/>

    <exclude body1="th_mp" body2="if_bs"/>
    <exclude body1="th_mp" body2="mf_bs"/>
    <exclude body1="th_mp" body2="rf_bs"/>
  </contact>

  <worldbody>
    <light name="leap_spotlight" mode="targetbodycom" target="palm" pos="3 0 4"/>
    <!-- Directly-controlled LEAP root: 6 joints on leap_mount, no freejoint -->
    <body name="leap_mount" pos="0 0 0.8" quat="1 0 0 0" childclass="leap_rh">
      <inertial mass="0.8" diaginertia="0.01 0.01 0.01" pos="0 0 0"/>
      <!-- 6-DoF joints (PD via P + joint damping + armature) -->
      <joint name="lm_x" type="slide" axis="1 0 0" range="-1 1" damping="2.0" armature="0.01"/>
      <joint name="lm_y" type="slide" axis="0 1 0" range="-1 1" damping="2.0" armature="0.01"/>
      <joint name="lm_z" type="slide" axis="0 0 1" range="0 1.5" damping="2.5" armature="0.015"/>
      <joint name="lm_yaw"   type="hinge" axis="0 0 1" range="-3.1416 3.1416" damping="1.0" armature="0.005"/>
      <joint name="lm_pitch" type="hinge" axis="0 1 0" range="-1.57 1.57" damping="1.0" armature="0.005"/>
      <joint name="lm_roll"  type="hinge" axis="1 0 0" range="-1.57 1.57" damping="1.0" armature="0.005"/>

      <geom name="leap_mount_visual" pos="0 0 0" quat="1 0 0 0" class="leap_visual" mesh="leap_mount"/>
      <geom name="leap_mount_collision_0" size="0.002 0.025 0.005" pos="0.0405 0.02 0.009" quat="0.57346234 0 0.81923192 0" type="box"/>
      <geom name="leap_mount_collision_1" size="0.005 0.005 0.005" pos="0.05 0.053 0.002" quat="0.4987168 0.64994038 -0.34910175 0.45495826" type="box"/>
      <site name="grasp_site" pos="0.11 0.0 0.03" group="4"/>
      <!-- The rest of the hand structure (palm and fingers) copied from leap_rh_mjx.xml -->
      <body name="palm" pos="0.124 -0.0305 -0.06045" quat="0 1 0 -0.175">
        <inertial pos="-0.049542 -0.042914 -0.010227" quat="0.565586 0.427629 -0.574956 0.408254" mass="0.237" diaginertia="0.000407345 0.000304759 0.000180736"/>
        <geom name="palm_visual" pos="-0.02 0.02575 -0.0347" quat="1 0 0 0" class="leap_visual" mesh="palm"/>
        <geom name="palm_collision_1" size="0.011 0.013 0.017" pos="-0.009 0.008 -0.011" type="box"/>
        <geom name="palm_collision_2" size="0.011 0.013 0.017" pos="-0.009 -0.037 -0.011" type="box"/>
        <geom name="palm_collision_3" size="0.011 0.013 0.017" pos="-0.009 -0.082 -0.011" type="box"/>
        <geom name="palm_collision_4" size="0.029 0.01 0.023" pos="-0.066 -0.078 -0.0115" quat="0.989016 0 0 -0.147806" type="box"/>
        <geom name="palm_collision_5" size="0.01 0.06 0.015" pos="-0.03 -0.035 -0.003" type="box"/>
        <geom name="palm_collision_6" size="0.005 0.06 0.01" pos="-0.032 -0.035 -0.024" quat="0.923956 0 0.382499 0" type="box"/>
        <geom name="palm_collision_7" size="0.012 0.058 0.023" pos="-0.048 -0.033 -0.0115" type="box"/>
        <geom name="palm_collision_8" size="0.022 0.026 0.023" pos="-0.078 -0.053 -0.0115" type="box"/>
        <geom name="palm_collision_9" size="0.002 0.018 0.017" pos="-0.098 -0.009 -0.006" type="box"/>
        <geom name="palm_collision_10" size="0.022 0.028 0.002" pos="-0.078 -0.003 0.01" type="box"/>
        <!-- ... Remaining fingers copied unchanged ... -->
      </body>
    </body>
  </worldbody>

  <actuator>
    <!-- 6-DoF base actuators on leap_mount (higher kp for stiff PD) -->
    <position name="lm_act_x"     joint="lm_x"     kp="200" forcerange="-600 600"/>
    <position name="lm_act_y"     joint="lm_y"     kp="200" forcerange="-600 600"/>
    <position name="lm_act_z"     joint="lm_z"     kp="200" forcerange="-600 600"/>
    <position name="lm_act_yaw"   joint="lm_yaw"   kp="80"  forcerange="-250 250"/>
    <position name="lm_act_pitch" joint="lm_pitch" kp="80"  forcerange="-250 250"/>
    <position name="lm_act_roll"  joint="lm_roll"  kp="80"  forcerange="-250 250"/>

    <!-- Finger actuators (same as leap_rh_mjx.xml) -->
    <position name="if_mcp_act" joint="if_mcp" class="mcp"/>
    <position name="if_rot_act" joint="if_rot" class="rot"/>
    <position name="if_pip_act" joint="if_pip" class="pip"/>
    <position name="if_dip_act" joint="if_dip" class="dip"/>
    <position name="mf_mcp_act" joint="mf_mcp" class="mcp"/>
    <position name="mf_rot_act" joint="mf_rot" class="rot"/>
    <position name="mf_pip_act" joint="mf_pip" class="pip"/>
    <position name="mf_dip_act" joint="mf_dip" class="dip"/>
    <position name="rf_mcp_act" joint="rf_mcp" class="mcp"/>
    <position name="rf_rot_act" joint="rf_rot" class="rot"/>
    <position name="rf_pip_act" joint="rf_pip" class="pip"/>
    <position name="rf_dip_act" joint="rf_dip" class="dip"/>
    <position name="th_cmc_act" joint="th_cmc" class="thumb_cmc"/>
    <position name="th_axl_act" joint="th_axl" class="thumb_axl"/>
    <position name="th_mcp_act" joint="th_mcp" class="thumb_mcp"/>
    <position name="th_ipl_act" joint="th_ipl" class="thumb_ipl"/>
  </actuator>
</mujoco>


