<mujoco model="leap_hand_6dof_ctrl">
  <compiler meshdir=""/>

  <!-- Include LEAP Hand (provides finger actuators) -->
  <include file="leap_rh_mjx.xml"/>
  <!-- Include shared reorientation cube (visual + physical) -->
  <include file="reorientation_cube.xml"/>
  <statistic center="0.15 0 0" extent="0.4" meansize="0.01"/>

  <option timestep="0.01" integrator="Euler" iterations="5" ls_iterations="8">
      <flag eulerdamp="disable"/>
  </option>

  <visual>
    <headlight diffuse=".8 .8 .8" ambient=".2 .2 .2" specular="1 1 1"/>
    <rgba force="1 0 0 1"/>
    <global azimuth="120" elevation="-20"/>
    <map force="0.01" stiffness="500"/>
    <scale forcewidth="0.1" contactwidth="0.5" contactheight="0.2"/>
    <quality shadowsize="8192"/>
  </visual>

  <asset>
    <texture type="2d" name="groundplane" builtin="checker" mark="edge" rgb1="1 1 1" rgb2="1 1 1" markrgb="0 0 0"
      width="300" height="300"/>
    <material name="groundplane" texture="groundplane" texuniform="true" texrepeat="5 5" reflectance="0"/>
  </asset>

  <default>
    <default class="base6dof">
      <joint damping="1e-3" armature="0.0" limited="true"/>
      <position kp="120"/>
    </default>
  </default>

  <worldbody>
    <!-- 6-DoF controllable base -->
    <body name="hand_base" pos="0 0 0.6" quat="0 1 0 0">
      <!-- Provide mass and rotational inertia so this moving base is physically valid -->
      <inertial mass="1.0" diaginertia="0.01 0.01 0.01" pos="0 0 0"/>
      <!-- Translate -->
      <joint name="base_x" type="slide" axis="1 0 0" range="-1.0 1.0" damping="50.0" armature="0.01" class="base6dof"/>
      <joint name="base_y" type="slide" axis="0 1 0" range="-1.0 1.0" damping="50.0" armature="0.01" class="base6dof"/>
      <joint name="base_z" type="slide" axis="0 0 1" range="-1.4 3.0" damping="50.5" armature="0.015" class="base6dof"/>
      <!-- Rotate (ZYX order: yaw, pitch, roll) -->
      <joint name="base_yaw"   type="hinge" axis="0 0 1" range="-3.1416 3.1416" damping="2.0" armature="0.005" class="base6dof"/>
      <joint name="base_pitch" type="hinge" axis="0 1 0" range="-1.57 1.57" damping="2.0" armature="0.005" class="base6dof"/>
      <joint name="base_roll"  type="hinge" axis="1 0 0" range="-6.2832 6.2832" damping="2.0" armature="0.005" class="base6dof"/>
      <site name="base_mount_site" size="0.01" rgba="0 0 1 0.6"/>
      
    </body>

    <geom name="floor" pos="0 0 -0.5" size="0 0 0.01" type="plane" 
    material="groundplane" contype="0" conaffinity="0" rgba="1 0 0 0.5"/>    
    
    <!-- Invisible physical ground for contact tests (keeps grid visual clean) -->
    <geom type="plane" name="ground_physical" pos="0 0 -0.5" size="0 0 0.01" contype="1" conaffinity="1"
          friction="0.8 0.01 0.0001" rgba="1 1 1 0"/>

    <!-- 回転は気にしないが、位置としての目標としてgoal cubeを設定する。 -->
    <body name="goal" mocap="true" pos="0.325 0.17 0.0475">
      <geom type="mesh" mesh="cube_mesh" material="dexcube" contype="0" conaffinity="0" density="0" group="2"/>
      <geom type="box" size=".035 .035 .035" mass=".108" group="3"/>
    </body>
    <camera name="cam" pos="1.2 0.0 0.9" xyaxes="0.0 -1.0 0.0 0.4 0.0 0.9"/>
  </worldbody>

    <sensor>
    <!-- cube. -->
    <framepos name="cube_position" objtype="body" objname="cube"/>
    <framequat name="cube_orientation" objtype="body" objname="cube"/>
    <framelinvel name="cube_linvel" objtype="body" objname="cube"/>
    <frameangvel name="cube_angvel" objtype="body" objname="cube"/>
    <frameangacc name="cube_angacc" objtype="body" objname="cube"/>
    <framezaxis name="cube_upvector" objtype="body" objname="cube"/>

    <!-- hand. -->
    <framepos name="palm_position" objtype="site" objname="grasp_site"/>
    <framepos name="th_tip_position" objtype="site" objname="th_tip" reftype="site" refname="grasp_site"/>
    <framepos name="if_tip_position" objtype="site" objname="if_tip" reftype="site" refname="grasp_site"/>
    <framepos name="mf_tip_position" objtype="site" objname="mf_tip" reftype="site" refname="grasp_site"/>
    <framepos name="rf_tip_position" objtype="site" objname="rf_tip" reftype="site" refname="grasp_site"/>


  </sensor>


  <!-- Weld LEAP to the controllable base. Adjust relpose if needed to match the intended mounting -->
  <equality>
    <!-- Overdamped weld to reduce oscillations -->
    <weld body1="hand_base" body2="leap_mount" solref="0.01 2" solimp="0.98 0.995 0.001" relpose="0 0 0 1 0 0 0"/>
  </equality>

  <actuator>
    <!-- Position controllers for 6-DoF base (RL action can write to these) -->
    <position name="act_base_x"     joint="base_x"     kp="200" forcerange="-600 600"/>
    <position name="act_base_y"     joint="base_y"     kp="200" forcerange="-600 600"/>
    <position name="act_base_z"     joint="base_z"     kp="200" forcerange="-600 600"/>
    <position name="act_base_yaw"   joint="base_yaw"   kp="80"  forcerange="-250 250"/>
    <position name="act_base_pitch" joint="base_pitch" kp="80"  forcerange="-250 250"/>
    <position name="act_base_roll"  joint="base_roll"  kp="80"  forcerange="-250 250"/>
  </actuator>

  <!-- Keyframe for initial pose/control targets (also resets cube pose) -->
  <keyframe>
    <!-- qpos order:
         base(6), leap_mount_freejoint(7), finger joints(16), cube_freejoint(7) -->
    <key name="home" qpos="
      0 0 0 0 0 0
      0 0 0.6 1 0 0 0
      0.8 0 0.8 0.8
      0.8 0 0.8 0.8
      0.8 0 0.8 0.8
      0.8 0.8 0.8 0
      0.11 0.0 -0.465 1 0 0 0"
      ctrl="
      0 0 0 0  0 0 0 0  0 0 0 0  0 0 0 0
      0 0 0.3  0 0 0"
      mpos="0.325 0.17 0.0475"
      mquat="1 0 0 0"/>
  </keyframe>
</mujoco>


