<mujoco model="leap_hand_6dof_ctrl">
  <compiler meshdir=""/>

  <!-- Include LEAP Hand (provides finger actuators) -->
  <include file="leap_rh_mjx.xml"/>
  <!-- Include shared reorientation cube (visual + physical) -->
  <include file="reorientation_cube.xml"/>
  <statistic center="0.15 0 0" extent="0.4" meansize="0.01"/>

  <option timestep="0.01" integrator="Euler" iterations="5" ls_iterations="8">
      <flag eulerdamp="disable"/>
  </option>

  <visual>
    <headlight diffuse=".8 .8 .8" ambient=".2 .2 .2" specular="1 1 1"/>
    <rgba force="1 0 0 1"/>
    <global azimuth="120" elevation="-20"/>
    <map force="0.01" stiffness="500"/>
    <scale forcewidth="0.1" contactwidth="0.5" contactheight="0.2"/>
    <quality shadowsize="8192"/>
  </visual>

  <asset>
    <texture type="2d" name="groundplane" builtin="checker" mark="edge" rgb1="1 1 1" rgb2="1 1 1" markrgb="0 0 0"
      width="300" height="300"/>
    <material name="groundplane" texture="groundplane" texuniform="true" texrepeat="5 5" reflectance="0"/>
  </asset>

  <default>
    <default class="base6dof">
      <joint damping="1e-3" armature="0.0" limited="true"/>
      <position kp="120"/>
    </default>
  </default>

  <worldbody>
    <!-- 6-DoF controllable base -->
    <body name="hand_base" pos="0 0 0.6" quat="0 1 0 0">
      <!-- Provide mass and rotational inertia so this moving base is physically valid -->
      <inertial mass="1.0" diaginertia="0.01 0.01 0.01" pos="0 0 0"/>
      <!-- Translate -->
      <joint name="base_x" type="slide" axis="1 0 0" range="-1.0 1.0" damping="50.0" armature="0.01" class="base6dof"/>
      <joint name="base_y" type="slide" axis="0 1 0" range="-1.0 1.0" damping="50.0" armature="0.01" class="base6dof"/>
      <joint name="base_z" type="slide" axis="0 0 1" range="-1.4 3.0" damping="50.5" armature="0.015" class="base6dof"/>
      <!-- Rotate (ZYX order: yaw, pitch, roll) -->
      <joint name="base_yaw"   type="hinge" axis="0 0 1" range="-3.1416 3.1416" damping="2.0" armature="0.005" class="base6dof"/>
      <joint name="base_pitch" type="hinge" axis="0 1 0" range="-1.57 1.57" damping="2.0" armature="0.005" class="base6dof"/>
      <joint name="base_roll"  type="hinge" axis="1 0 0" range="-6.2832 6.2832" damping="2.0" armature="0.005" class="base6dof"/>
      <site name="base_mount_site" size="0.01" rgba="0 0 1 0.6"/>
      
    </body>

    <geom name="floor" pos="0 0 -0.5" size="0 0 0.01" type="plane" 
    material="groundplane" contype="0" conaffinity="0" rgba="1 0 0 0.5"/>    
    
    <!-- Invisible physical ground for contact tests (keeps grid visual clean) -->
    <geom type="plane" name="ground_physical" pos="0 0 -0.5" size="0 0 0.01" contype="1" conaffinity="1"
          friction="0.8 0.01 0.0001" rgba="1 1 1 0"/>

    <!-- 回転は気にしないが、位置としての目標としてgoal cubeを設定する。 -->
    <body name="goal" mocap="true" pos="0.325 0.17 0.0475">
      <geom type="mesh" mesh="cube_mesh" material="dexcube" contype="0" conaffinity="0" density="0" group="2"/>
      <geom type="box" size=".035 .035 .035" mass=".108" group="3"/>
    </body>
    <camera name="cam" pos="1.2 0.0 0.9" xyaxes="0.0 -1.0 0.0 0.4 0.0 0.9"/>
  </worldbody>

    <sensor>
    <!-- cube. -->
    <framepos name="cube_position" objtype="body" objname="cube"/>
    <framequat name="cube_orientation" objtype="body" objname="cube"/>
    <framelinvel name="cube_linvel" objtype="body" objname="cube"/>
    <frameangvel name="cube_angvel" objtype="body" objname="cube"/>
    <frameangacc name="cube_angacc" objtype="body" objname="cube"/>
    <framezaxis name="cube_upvector" objtype="body" objname="cube"/>

    <!-- hand. -->
    <framepos name="palm_position" objtype="site" objname="grasp_site"/>
    <framepos name="th_tip_position" objtype="site" objname="th_tip" reftype="site" refname="grasp_site"/>
    <framepos name="if_tip_position" objtype="site" objname="if_tip" reftype="site" refname="grasp_site"/>
    <framepos name="mf_tip_position" objtype="site" objname="mf_tip" reftype="site" refname="grasp_site"/>
    <framepos name="rf_tip_position" objtype="site" objname="rf_tip" reftype="site" refname="grasp_site"/>

    <!-- base (hand_base) pose and velocities -->
    <framepos name="base_position" objtype="body" objname="hand_base"/>
    <framequat name="base_orientation" objtype="body" objname="hand_base"/>
    <framelinvel name="base_linvel" objtype="body" objname="hand_base"/>
    <frameangvel name="base_angvel" objtype="body" objname="hand_base"/>

    <!-- base joint states -->
    <jointpos name="base_x_pos" joint="base_x"/>
    <jointpos name="base_y_pos" joint="base_y"/>
    <jointpos name="base_z_pos" joint="base_z"/>
    <jointpos name="base_yaw_pos" joint="base_yaw"/>
    <jointpos name="base_pitch_pos" joint="base_pitch"/>
    <jointpos name="base_roll_pos" joint="base_roll"/>

    <jointvel name="base_x_vel" joint="base_x"/>
    <jointvel name="base_y_vel" joint="base_y"/>
    <jointvel name="base_z_vel" joint="base_z"/>
    <jointvel name="base_yaw_vel" joint="base_yaw"/>
    <jointvel name="base_pitch_vel" joint="base_pitch"/>
    <jointvel name="base_roll_vel" joint="base_roll"/>

    
    <!-- goal. -->
    <framepos name="cube_goal_position" objtype="body" objname="goal"/>
    <framequat name="cube_goal_orientation" objtype="body" objname="goal"/>


  </sensor>


  <!-- Weld LEAP to the controllable base. Adjust relpose if needed to match the intended mounting -->
  <equality>
    <!-- Overdamped weld to reduce oscillations -->
    <weld body1="hand_base" body2="leap_mount" solref="0.01 2" solimp="0.98 0.995 0.001" relpose="0 0 0 1 0 0 0"/>
  </equality>

  <actuator>
    <!-- Position controllers for 6-DoF base (RL action can write to these) -->
    <position name="act_base_x"     joint="base_x"     kp="200" forcerange="-600 600"/>
    <position name="act_base_y"     joint="base_y"     kp="200" forcerange="-600 600"/>
    <position name="act_base_z"     joint="base_z"     kp="200" forcerange="-600 600"/>
    <position name="act_base_yaw"   joint="base_yaw"   kp="80"  forcerange="-250 250"/>
    <position name="act_base_pitch" joint="base_pitch" kp="80"  forcerange="-250 250"/>
    <position name="act_base_roll"  joint="base_roll"  kp="80"  forcerange="-250 250"/>
  </actuator>

  <!-- Keyframe for initial pose/control targets (also resets cube pose) -->
  <keyframe>
    <!-- qpos order:
         base(6), leap_mount_freejoint(7), finger joints(16), cube_freejoint(7) -->

    <key name="home" qpos="
      0.68 0.78 -0.31608 0.000307632 -0.968342 -1.26824e-05 0.249627 0.706534 -9.40659e-05 0.499187 0.764972 0.556337 -8.01922e-05 0.762973 -0.365415 0.626353 0.020783 1.40298 0.403332 1.6051 0.335327 -0.465174 0.832772 0.778537 0.796473 -0.465057 0.706203 0.706203 0.0357402 0.0357402 0.68 -0.78 0.915788 -8.37347e-17 -0.49089 0.000261597"
      qvel="
      -4.68571e-15 -5.0496e-15 2.12138e-15 -1.33856e-15 -3.46942e-16 2.61642e-16 3.63506e-15 -4.55496e-16 4.66854e-16 3.40429e-15 -5.28228e-15 -4.45993e-18 -5.37553e-15 -2.72037e-15 -5.33398e-15 -1.4865e-16 -1.09853e-14 -2.66017e-15 -1.06653e-14 2.69029e-15 2.61078e-15 5.37259e-15 -5.27737e-15 -7.89989e-16 -1.49461e-15 -1.34451e-14 4.48657e-15 1.2027e-15 -5.00556e-15 5.12734e-15 -4.73039e-15 2.48606e-16 1.88072e-16 -5.64889e-16"
      ctrl="
      0.69088 0 0.49822 0.76576 0.53824 0 0.76123 -0.366 0.61456 0.02094 1.4068 0.40456 1.6054 0.33504 -0.47 0.8335 0.68 -0.78 0.83 0 -0.48 0"
      mpos="0.325 0.17 0.0475"
      mquat="1 0 0 0"/>

    <key name="not_beautiful_meaningless" qpos="
      0 0 0 0 0 0
      0 0 0.6 1 0 0 0
      0.8 0 0.8 0.8
      0.8 0 0.8 0.8
      0.8 0 0.8 0.8
      0.8 0.8 0.8 0
      0.11 0.0 -0.465 1 0 0 0"
      ctrl="
      0 0 0 0  0 0 0 0  0 0 0 0  0 0 0 0
      0 0 0.3  0 0 0"
      mpos="0.325 0.17 0.0475"
      mquat="1 0 0 0"/>

  </keyframe>
</mujoco>


